{-# LANGUAGE CPP #-}

-- | Exception handling. The interface here combines ideas from the following
-- three libraries in a somewhat idiosyncratic way:
--
-- * [annotated-exception](https://hackage.haskell.org/package/annotated-exception)
-- * [exceptions](https://hackage.haskell.org/package/exceptions)
-- * [safe-exceptions](https://hackage.haskell.org/package/safe-exceptions)
--
-- We have the following goals:
--
-- 1. Typeclass abstraction: @exceptions@'s
--    'MonadThrow'\/'MonadCatch'\/'MonadMask' hierarchy.
-- 2. Throw exceptions w/ 'CallStack': Inspired by @annotated-exception@, we
--    use a custom type 'ExceptionCS' for this purpose. This functionality may
--    be removed once GHC natively supports combining exceptions and
--    'CallStack' (tentatively GHC 9.8). See the following proposal for more
--    information:
--    https://github.com/ghc-proposals/ghc-proposals/pull/330
--
-- 3. Throw/catch exceptions in accordance with @safe-exceptions@: That is,
--    do not throw or catch async exceptions. We do not actually re-export
--    @safe-exceptions@ functions; the functions here are bespoke, primarily
--    to add `HasCallStack` constraints.
--
-- 4. Masking/bracket uses 'Ex.mask', not 'Ex.uninterruptibleMask': We take
--    the position that 'Ex.uninterruptibleMask' should /not/ be the default
--    behavior, as legitimate uses are rare, and for those corner cases,
--    deadlocks are worse than interruptible operations receiving async
--    exceptions.
--
-- The API exported here is not comprehensive vis-Ã -vis any of the mentioned
-- libraries, so if more functionality is required, a direct dependency
-- will be necessary.
--
-- Note that, like @safe-exceptions@, the typeclass methods for
-- 'MonadThrow' ('throwM') and 'MonadCatch' ('catch') are __not__ exported
-- here because they are overridden to prevent catching async exceptions.
-- This means that if one needs to manually write an instance for any of
-- those classes, then a dependency on @exceptions@ is required.
--
-- @since 0.1
module Effects.Exception
  ( -- * Global mechanisms
    MonadGlobalException (..),

    -- * CallStack
    -- $callstack
    ExceptionCS (..),
    throwCS,
    catchCS,
    catchAnyCS,
    handleCS,
    handleAnyCS,
    tryCS,
    tryAnyCS,
    addCS,
    addOuterCS,

    -- ** Utils
    displayNoCS,

    -- * Basic exceptions
    -- $basics

    -- ** Throwing
    MonadThrow,
    throwM,
    SafeEx.throwString,

    -- ** Catching
    MonadCatch,
    catch,
    catchAny,
    handle,
    handleAny,
    try,
    tryAny,
    Handler (..),
    catches,
    onException,
    SafeEx.catchIOError,

    -- ** Masking
    -- $masking
    MonadMask (..),
    Ex.ExitCase (..),
    Ex.mask_,
    Ex.uninterruptibleMask_,
    Ex.bracket,
    Ex.bracket_,
    Ex.finally,
    Ex.bracketOnError,

    -- ** Utils
    SafeEx.SyncExceptionWrapper,
    SafeEx.AsyncExceptionWrapper,
    SafeEx.toSyncException,
    SafeEx.toAsyncException,
    SafeEx.isSyncException,
    SafeEx.isAsyncException,

    -- ** Exiting
    -- $exit
    ExitCode (..),

    -- ** Functions
    exitFailure,
    exitSuccess,
    exitWith,

    -- * Misc
    CallStack,
    Exception (..),
    HasCallStack,
    SomeException,
    IOException,
    SafeEx.StringException,
  )
where

import Control.DeepSeq (NFData)
import Control.Exception.Safe qualified as SafeEx
import Control.Monad.Catch
  ( Exception (displayException, fromException, toException),
    Handler (Handler),
    MonadCatch,
    MonadMask (generalBracket, mask, uninterruptibleMask),
    MonadThrow,
    SomeException (SomeException),
  )
import Control.Monad.Catch qualified as Ex
import Control.Monad.Trans.Class (MonadTrans (lift))
import Control.Monad.Trans.Reader (ReaderT, ask, runReaderT)
import Data.Set qualified as Set
import Data.Typeable (cast)
import GHC.Conc.Sync qualified as Sync
import GHC.Generics (Generic)
import GHC.IO.Exception (IOErrorType (InvalidArgument), IOException (IOError))
import GHC.Stack
  ( CallStack,
    HasCallStack,
    callStack,
    prettyCallStack,
    withFrozenCallStack,
  )
import GHC.Stack.Types (SrcLoc (SrcLoc), fromCallSiteList, getCallStack)
import System.Exit (ExitCode (ExitFailure, ExitSuccess))

-------------------------------------------------------------------------------
--                           MonadGlobalException                            --
-------------------------------------------------------------------------------

-- | Effect for global exception mechanisms.
--
-- @since 0.1
class (Monad m) => MonadGlobalException m where
  -- | Lifted 'Sync.setUncaughtExceptionHandler'.
  --
  -- @since 0.1
  setUncaughtExceptionHandler :: (HasCallStack) => (SomeException -> m ()) -> m ()

  -- | Lifted 'Sync.getUncaughtExceptionHandler'.
  --
  -- @since 0.1
  getUncaughtExceptionHandler :: (HasCallStack) => m (SomeException -> m ())

-- | @since 0.1
instance MonadGlobalException IO where
  setUncaughtExceptionHandler = addCS . Sync.setUncaughtExceptionHandler
  {-# INLINEABLE setUncaughtExceptionHandler #-}

  getUncaughtExceptionHandler = addCS Sync.getUncaughtExceptionHandler
  {-# INLINEABLE getUncaughtExceptionHandler #-}

-- | @since 0.1
instance (MonadGlobalException m) => MonadGlobalException (ReaderT env m) where
  setUncaughtExceptionHandler f =
    ask >>= \e ->
      lift $ setUncaughtExceptionHandler (\ex -> runReaderT (f ex) e)
  {-# INLINEABLE setUncaughtExceptionHandler #-}

  getUncaughtExceptionHandler =
    ask >>= \e -> lift (runReaderT getUncaughtExceptionHandler e)
  {-# INLINEABLE getUncaughtExceptionHandler #-}

-------------------------------------------------------------------------------
--                                 CallStack                                 --
-------------------------------------------------------------------------------

-- NOTE: Post GHC 9.8, this entire section will be removed. We will instead
-- use GHC's native exception handling.

-- $callstack
-- The callstack API and implementation is heavily inspired by the excellent
-- [annotated-exception](https://hackage.haskell.org/package/annotated-exception)
-- library.
--
-- The primary difference is that @annotated-exception@ is more general and
-- comprehensive; the primary exception type allows one to tie arbitrary
-- data to its exceptions.
--
-- By comparison, the functionality here is only concerned with 'CallStack'.
-- That enables both the implementation and usage to be simpler, if you only
-- have the modest goal of obtaining exception callstacks.
--
-- Another difference is that 'ExceptionCS'\'s 'Show' instance uses
-- its 'displayException', which pretty-prints the 'CallStack'. This decision
-- is due to many functions/ibraries defaulting to 'Show', so this way is
-- more conservative if you really want stacktraces, at the cost of some
-- transparency.
--
-- Note that if an exception @e@ is thrown with 'throwCS', you can
-- no longer catch it with normal @catch \@e@, as it is now a
-- @ExceptionCS e@. You can instead use @catchCS \@e@.

-- | Attaches a 'CallStack' to an arbitrary exception. The 'Show' instance
-- uses 'displayException' i.e. the underlying exceptions' 'displayException'
-- and pretty-prints the 'CallStack' due to some libraries (e.g. testing)
-- defaulting to 'Show' when printing exceptions.
--
-- @since 0.1
data ExceptionCS e = MkExceptionCS e CallStack
  deriving stock
    ( -- | @since 0.1
      Generic,
      -- | @since 0.1
      Functor
    )
  deriving anyclass
    ( -- | @since 0.1
      NFData
    )

-- | @since 0.1
instance Applicative ExceptionCS where
  pure x = MkExceptionCS x callStack

  MkExceptionCS f cs <*> MkExceptionCS x cs' =
    MkExceptionCS (f x) (mergeCallStack cs cs')

-- | @since 0.1
instance Monad ExceptionCS where
  MkExceptionCS x cs >>= f =
    let MkExceptionCS x' cs' = f x
     in MkExceptionCS x' (mergeCallStack cs cs')

-- | Alias for 'displayException'.
--
-- @since 0.1
instance (Exception e) => Show (ExceptionCS e) where
  show = displayException

-- | @since 0.1
instance (Exception e) => Exception (ExceptionCS e) where
  -- Converting underlying exception so that we can predictably convert to
  -- ExceptionCS SomeException
  toException (MkExceptionCS ex cs) =
    tryFlatten $ SomeException (MkExceptionCS (toException ex) cs)

  fromException someEx@(SomeException innerEx)
    -- innerEx == ExceptionCS e
    -- ==> ExceptionCS e
    | Just x <- cast innerEx = Just x
    -- innerEx == ExceptionCS innerSomeEx@SomeException
    -- innerSomeEx == e
    -- ==> ExceptionCS e
    | Just (MkExceptionCS (innerSomeEx :: SomeException) cs) <- cast innerEx,
      Just x <- fromException innerSomeEx =
        Just $ MkExceptionCS x cs
    -- SomeException == e
    -- ==> ExceptionCS e
    | Just x <- fromException someEx = Just $ pure x
    -- We did our best
    | otherwise = Nothing

  displayException (MkExceptionCS e cs) =
    mconcat
      [ displayException e,
        "\n",
        prettyCallStack cs
      ]

flatten :: ExceptionCS (ExceptionCS e) -> ExceptionCS e
flatten (MkExceptionCS (MkExceptionCS ex old) new) =
  MkExceptionCS ex (mergeCallStack old new)

tryFlatten :: SomeException -> SomeException
tryFlatten ex =
  case fromException ex of
    Just (ex' :: ExceptionCS (ExceptionCS SomeException)) ->
      SomeException $ flatten ex'
    Nothing ->
      ex

-- | Wraps an exception in 'ExceptionCS' and rethrows. If the @e@ is
-- also an 'ExceptionCS', the callStacks are merged.
--
-- @since 0.1
throwCS ::
  forall m e a.
  (Exception e, HasCallStack, MonadThrow m) =>
  e ->
  m a
throwCS ex =
  withFrozenCallStack $ throwM $ MkExceptionCS ex callStack
{-# INLINEABLE throwCS #-}

-- | Catches both @e@ and @ExceptionCS e@. The given handler is
-- wrapped in 'addCS'.
--
-- @since 0.1
catchCS ::
  forall m e a.
  (Exception e, HasCallStack, MonadCatch m) =>
  m a ->
  (e -> m a) ->
  m a
catchCS action handler =
  withFrozenCallStack
    catches
    action
    [ Handler $ \ex -> addCS $ handler ex,
      -- "Forget" about the callstack unless another is raised.
      Handler $ \(MkExceptionCS ex cs) -> addOuterCS cs $ handler ex
    ]
{-# INLINEABLE catchCS #-}

-- | 'catchCS' specialized to all synchronous exceptions.
--
-- @since 0.1
catchAnyCS ::
  forall m a.
  (HasCallStack, MonadCatch m) =>
  m a ->
  (SomeException -> m a) ->
  m a
catchAnyCS = catchCS
{-# INLINEABLE catchAnyCS #-}

-- | Flipped 'catchCS'.
--
-- @since 0.1
handleCS ::
  forall m e a.
  (Exception e, HasCallStack, MonadCatch m) =>
  (e -> m a) ->
  m a ->
  m a
handleCS = flip catchCS
{-# INLINEABLE handleCS #-}

-- | 'handleCS' specialized to 'SomeException'.
--
-- @since 0.1
handleAnyCS ::
  forall m a.
  (HasCallStack, MonadCatch m) =>
  (SomeException -> m a) ->
  m a ->
  m a
handleAnyCS = handleCS
{-# INLINEABLE handleAnyCS #-}

-- | Try for 'catchCS'.
--
-- @since 0.1
tryCS ::
  forall m e a.
  (Exception e, MonadCatch m) =>
  m a ->
  m (Either e a)
tryCS m = (Right <$> m) `catchCS` (pure . Left)
{-# INLINEABLE tryCS #-}

-- | 'tryCS' specialized to 'SomeException'.
--
-- @since 0.1
tryAnyCS ::
  forall m a.
  (MonadCatch m) =>
  m a ->
  m (Either SomeException a)
tryAnyCS = tryCS
{-# INLINEABLE tryAnyCS #-}

-- | Turns any caught exceptions @e@ into an @ExceptionCS e@ with
-- attached 'CallStack' and rethrows.
--
-- @since 0.1
addCS :: forall m a. (HasCallStack, MonadCatch m) => m a -> m a
addCS = withFrozenCallStack addOuterCS callStack
{-# INLINEABLE addCS #-}

-- | Like 'addCS', except it merges the given "outer callstack" with
-- the one generated by a caught exception.
--
-- @since 0.1
addOuterCS :: forall m a. (HasCallStack, MonadCatch m) => CallStack -> m a -> m a
addOuterCS outerCS m =
  m `catch` \(ex :: SomeException) ->
    throwM $ case fromException ex of
      Just (MkExceptionCS (innerEx :: SomeException) innerCS) ->
        MkExceptionCS
          innerEx
          (innerCS `mergeCallStack` outerCS `mergeCallStack` callStack)
      Nothing -> MkExceptionCS ex (outerCS `mergeCallStack` callStack)
{-# INLINEABLE addOuterCS #-}

mergeCallStack :: CallStack -> CallStack -> CallStack
mergeCallStack innerCS outerCS =
  fromCallSiteList $
    fmap (fmap fromSrcLocOrd) $
      ordNub $
        fmap (fmap toSrcLocOrd) $
          getCallStack innerCS <> getCallStack outerCS

toSrcLocOrd :: SrcLoc -> ([Char], [Char], [Char], Int, Int, Int, Int)
toSrcLocOrd (SrcLoc a b c d e f g) =
  (a, b, c, d, e, f, g)

fromSrcLocOrd :: ([Char], [Char], [Char], Int, Int, Int, Int) -> SrcLoc
fromSrcLocOrd (a, b, c, d, e, f, g) =
  SrcLoc a b c d e f g

ordNub :: (Ord a) => [a] -> [a]
ordNub = go Set.empty
  where
    go _ [] = []
    go s (x : xs)
      | Set.member x s = go s xs
      | otherwise = x : go (Set.insert x s) xs

-- | Like 'displayException', except it has specific logic to skip any
-- found 'CallStack's.
--
-- @since 0.1
displayNoCS :: forall e. (Exception e) => e -> String
displayNoCS ex =
  case fromException (toException ex) of
    Nothing -> displayException ex
    Just (MkExceptionCS (ex' :: SomeException) _) -> displayException ex'

-------------------------------------------------------------------------------
--                                 Exceptions                                --
-------------------------------------------------------------------------------

-- $basics
-- The functionality here is a mix of @exceptions@ and @safe-exceptions@.
-- On the one hand, we reuse @exceptions@' typeclass hierarchy. On the other
-- hand, the functions we export (e.g. `throwM`, `catch`) are reimplemented
-- with @safe-exceptions@' philosophy: by default, do not throw or catch
-- async exceptions. The only reason we do not directly export all
-- @safe-exceptions@' functions is due to them missing `HasCallStack`
-- constraints.

-- | Run an action only if an exception is thrown in the main action. The
-- exception is not caught, simply rethrown.
--
-- /NOTE/ The action is only run if an /exception/ is thrown. If the monad
-- supports other ways of aborting the computation, the action won't run if
-- those other kinds of errors are thrown. See 'onError'.
--
-- /NOTE/ This is __not__ the @onException@ re-exported from either
-- @exceptions@ or @safe-exceptions@. Why? The @exceptions@ variant reuses its
-- @catch@, which does not have the async exception behavior we want
-- (i.e. do not catch async exceptions). The @safe-exceptions@ version, on the
-- other hand, use its bracket functions, meaning it performs
-- @uninterruptibleMask@, which we also do not want.
--
-- Hence this version, which is based on 'catchAny' i.e. it does not catch
-- any asynchronous exceptions, nor does it invoke any masking.
--
-- @since 0.1
onException :: forall m a b. (HasCallStack, MonadCatch m) => m a -> m b -> m a
onException action handler =
  withFrozenCallStack catchAny action (\e -> handler *> throwM e)
{-# INLINEABLE onException #-}

-- Using the same idea from exceptions. We generally want HasCallStack on our
-- functions, but only if exceptions also has them (0.10.6), otherwise we
-- receive -Wredundant-constraint warnings.

#if MIN_VERSION_exceptions(0,10,6)
# define HAS_CALL_STACK HasCallStack
#else
# define HAS_CALL_STACK ()
#endif

-- | Like 'Ex.throwM' but any thrown asynchronous exceptions will be thrown
-- synchronously via 'toSyncException'.
--
-- @since 0.1
throwM :: (HAS_CALL_STACK) => (MonadThrow m, Exception e) => e -> m a
throwM = Ex.throwM . SafeEx.toSyncException

-- | Like upstream 'Ex.catch', but will not catch asynchronous exceptions.
--
-- @since 0.1
catch ::
  forall m e a.
  (HAS_CALL_STACK) =>
  ( MonadCatch m,
    Exception e
  ) =>
  m a ->
  (e -> m a) ->
  m a
catch f g =
  f `Ex.catch` \e ->
    if SafeEx.isSyncException e
      then g e
      else -- intentionally rethrowing an async exception synchronously,
      -- since we want to preserve async behavior
        Ex.throwM e

-- | 'catch' specialized to all synchronous exceptions.
--
-- @since 0.1
catchAny ::
  forall m a.
  (HAS_CALL_STACK) =>
  ( MonadCatch m
  ) =>
  m a ->
  (SomeException -> m a) ->
  m a
catchAny = catch

-- | Flipped version of 'catch'.
--
-- @since 0.1
handle ::
  forall m e a.
  (HAS_CALL_STACK) =>
  ( MonadCatch m,
    Exception e
  ) =>
  (e -> m a) ->
  m a ->
  m a
handle = flip catch

-- | Flipped version of 'catchAny'.
--
-- @since 0.1
handleAny ::
  forall m a.
  (HAS_CALL_STACK) =>
  (MonadCatch m) =>
  (SomeException -> m a) ->
  m a ->
  m a
handleAny = flip catchAny

-- | Like upstream 'Ex.try', but will not catch asynchronous exceptions.
--
-- @since 0.1
try ::
  forall m e a.
  (HAS_CALL_STACK) =>
  ( MonadCatch m,
    Exception e
  ) =>
  m a ->
  m (Either e a)
try f = catch (fmap Right f) (pure . Left)

-- | 'try' specialized to catch all synchronous exceptions.
--
-- @since 0.1
tryAny ::
  forall m a.
  (HAS_CALL_STACK) =>
  (MonadCatch m) =>
  m a ->
  m (Either SomeException a)
tryAny = try

-- | Like upstream 'Ex.catches', but will not catch asynchronous exceptions.
--
-- @since 0.1
catches ::
  forall m a.
  (HAS_CALL_STACK) =>
  (MonadCatch m) =>
  m a ->
  [Handler m a] ->
  m a
catches io handlers = io `catch` catchesHandler handlers

catchesHandler ::
  forall m a.
  (HAS_CALL_STACK) =>
  (MonadThrow m) =>
  [Handler m a] ->
  SomeException ->
  m a
catchesHandler handlers e = foldr tryHandler (throwM e) handlers
  where
    tryHandler (Handler handler) res = maybe res handler (fromException e)

-------------------------------------------------------------------------------
--                                    Exit                                   --
-------------------------------------------------------------------------------

-- $exit
-- These functions represent 'System.Exit'. 'System.Exit.die' can be found
-- in "Effects.FileSystem.HandleWriter".

-- | The computation 'exitFailure' is equivalent to
-- 'exitWith' @(@'ExitFailure' /exitfail/@)@,
-- where /exitfail/ is implementation-dependent.
--
-- @since 0.1
exitFailure :: (HAS_CALL_STACK) => (MonadThrow m) => m a
exitFailure = exitWith (ExitFailure 1)
{-# INLINEABLE exitFailure #-}

-- | The computation 'exitSuccess' is equivalent to
-- 'exitWith' 'ExitSuccess', It terminates the program
-- successfully.
--
-- @since 0.1
exitSuccess :: (HAS_CALL_STACK) => (MonadThrow m) => m a
exitSuccess = exitWith ExitSuccess
{-# INLINEABLE exitSuccess #-}

-- | Computation 'exitWith' @code@ throws 'ExitCode' @code@.
-- Normally this terminates the program, returning @code@ to the
-- program's caller.
--
-- On program termination, the standard 'Handle's 'stdout' and
-- 'stderr' are flushed automatically; any other buffered 'Handle's
-- need to be flushed manually, otherwise the buffered data will be
-- discarded.
--
-- A program that fails in any other way is treated as if it had
-- called 'exitFailure'.
-- A program that terminates successfully without calling 'exitWith'
-- explicitly is treated as if it had called 'exitWith' 'ExitSuccess'.
--
-- As an 'ExitCode' is not an 'IOError', 'exitWith' bypasses
-- the error handling in the 'IO' monad and cannot be intercepted by
-- 'catch' from the "Prelude". However it is a 'Control.Exception.SomeException', and can
-- be caught using the functions of "Control.Exception". This means
-- that cleanup computations added with 'Control.Exception.bracket'
-- (from "Control.Exception") are also executed properly on 'exitWith'.
--
-- Note: in GHC, 'exitWith' should be called from the main program
-- thread in order to exit the process. When called from another
-- thread, 'exitWith' will throw an 'ExitException' as normal, but the
-- exception will not cause the process itself to exit.
--
-- @since 0.1
exitWith :: (HAS_CALL_STACK) => (MonadThrow m) => ExitCode -> m a
exitWith ExitSuccess = throwCS ExitSuccess
exitWith code@(ExitFailure n)
  | n /= 0 = throwCS code
  | otherwise =
      throwCS
        ( IOError
            Nothing
            InvalidArgument
            "exitWith"
            "ExitFailure 0"
            Nothing
            Nothing
        )
{-# INLINEABLE exitWith #-}

-- $masking
-- This section directly reexports @exceptions@' functions: we favor its
-- 'mask' over @safe-exceptions@' 'uninterruptibleMask'.
